Traceback (most recent call last):
  File "/Users/aizawa/opt/anaconda3/envs/py39-ml/lib/python3.9/site-packages/jupyter_cache/executors/utils.py", line 51, in single_nb_execution
    executenb(
  File "/Users/aizawa/opt/anaconda3/envs/py39-ml/lib/python3.9/site-packages/nbclient/client.py", line 1204, in execute
    return NotebookClient(nb=nb, resources=resources, km=km, **kwargs).execute()
  File "/Users/aizawa/opt/anaconda3/envs/py39-ml/lib/python3.9/site-packages/nbclient/util.py", line 84, in wrapped
    return just_run(coro(*args, **kwargs))
  File "/Users/aizawa/opt/anaconda3/envs/py39-ml/lib/python3.9/site-packages/nbclient/util.py", line 62, in just_run
    return loop.run_until_complete(coro)
  File "/Users/aizawa/opt/anaconda3/envs/py39-ml/lib/python3.9/asyncio/base_events.py", line 647, in run_until_complete
    return future.result()
  File "/Users/aizawa/opt/anaconda3/envs/py39-ml/lib/python3.9/site-packages/nbclient/client.py", line 663, in async_execute
    await self.async_execute_cell(
  File "/Users/aizawa/opt/anaconda3/envs/py39-ml/lib/python3.9/site-packages/nbclient/client.py", line 965, in async_execute_cell
    await self._check_raise_for_error(cell, cell_index, exec_reply)
  File "/Users/aizawa/opt/anaconda3/envs/py39-ml/lib/python3.9/site-packages/nbclient/client.py", line 862, in _check_raise_for_error
    raise CellExecutionError.from_cell_and_msg(cell, exec_reply_content)
nbclient.exceptions.CellExecutionError: An error occurred while executing the following cell:
------------------
a = 3
b = 3
if a == b:
print(f'{a}と{b}は等しいです．') # if文の後にインデントを入れ忘れている
------------------

[0;36m  Input [0;32mIn [23][0;36m[0m
[0;31m    print(f'{a}と{b}は等しいです．') # if文の後にインデントを入れ忘れている[0m
[0m    ^[0m
[0;31mIndentationError[0m[0;31m:[0m expected an indented block

IndentationError: expected an indented block (4061242926.py, line 4)

