Traceback (most recent call last):
  File "/Users/aizawa/opt/anaconda3/envs/py39-ml/lib/python3.9/site-packages/jupyter_cache/executors/utils.py", line 51, in single_nb_execution
    executenb(
  File "/Users/aizawa/opt/anaconda3/envs/py39-ml/lib/python3.9/site-packages/nbclient/client.py", line 1204, in execute
    return NotebookClient(nb=nb, resources=resources, km=km, **kwargs).execute()
  File "/Users/aizawa/opt/anaconda3/envs/py39-ml/lib/python3.9/site-packages/nbclient/util.py", line 84, in wrapped
    return just_run(coro(*args, **kwargs))
  File "/Users/aizawa/opt/anaconda3/envs/py39-ml/lib/python3.9/site-packages/nbclient/util.py", line 62, in just_run
    return loop.run_until_complete(coro)
  File "/Users/aizawa/opt/anaconda3/envs/py39-ml/lib/python3.9/asyncio/base_events.py", line 647, in run_until_complete
    return future.result()
  File "/Users/aizawa/opt/anaconda3/envs/py39-ml/lib/python3.9/site-packages/nbclient/client.py", line 663, in async_execute
    await self.async_execute_cell(
  File "/Users/aizawa/opt/anaconda3/envs/py39-ml/lib/python3.9/site-packages/nbclient/client.py", line 965, in async_execute_cell
    await self._check_raise_for_error(cell, cell_index, exec_reply)
  File "/Users/aizawa/opt/anaconda3/envs/py39-ml/lib/python3.9/site-packages/nbclient/client.py", line 862, in _check_raise_for_error
    raise CellExecutionError.from_cell_and_msg(cell, exec_reply_content)
nbclient.exceptions.CellExecutionError: An error occurred while executing the following cell:
------------------
X = np.load('data.npy')
y = np.load('target.npy')
------------------

[0;31m---------------------------------------------------------------------------[0m
[0;31mValueError[0m                                Traceback (most recent call last)
Input [0;32mIn [4][0m, in [0;36m<cell line: 1>[0;34m()[0m
[0;32m----> 1[0m X [38;5;241m=[39m [43mnp[49m[38;5;241;43m.[39;49m[43mload[49m[43m([49m[38;5;124;43m'[39;49m[38;5;124;43mdata.npy[39;49m[38;5;124;43m'[39;49m[43m)[49m
[1;32m      2[0m y [38;5;241m=[39m np[38;5;241m.[39mload([38;5;124m'[39m[38;5;124mtarget.npy[39m[38;5;124m'[39m)

File [0;32m~/opt/anaconda3/envs/py39-ml/lib/python3.9/site-packages/numpy/lib/npyio.py:445[0m, in [0;36mload[0;34m(file, mmap_mode, allow_pickle, fix_imports, encoding)[0m
[1;32m    442[0m [38;5;28;01melse[39;00m:
[1;32m    443[0m     [38;5;66;03m# Try a pickle[39;00m
[1;32m    444[0m     [38;5;28;01mif[39;00m [38;5;129;01mnot[39;00m allow_pickle:
[0;32m--> 445[0m         [38;5;28;01mraise[39;00m [38;5;167;01mValueError[39;00m([38;5;124m"[39m[38;5;124mCannot load file containing pickled data [39m[38;5;124m"[39m
[1;32m    446[0m                          [38;5;124m"[39m[38;5;124mwhen allow_pickle=False[39m[38;5;124m"[39m)
[1;32m    447[0m     [38;5;28;01mtry[39;00m:
[1;32m    448[0m         [38;5;28;01mreturn[39;00m pickle[38;5;241m.[39mload(fid, [38;5;241m*[39m[38;5;241m*[39mpickle_kwargs)

[0;31mValueError[0m: Cannot load file containing pickled data when allow_pickle=False
ValueError: Cannot load file containing pickled data when allow_pickle=False

